Workbook

Sheet Risk Management Dashboard
A1: Project Name: | C1: ABC
A2: Client
A3: Report Date : | C3: 46083
AD22: no | AE22: match
AD23: 1 | AE23: =IFERROR(MATCH(AD23,'Risk Register'!$K$2:$K$880,0),"") -> 7
AD24: 2 | AE24: =IFERROR(MATCH(AD24,'Risk Register'!$K$2:$K$880,0),"") -> 4
AD25: 3 | AE25: =IFERROR(MATCH(AD25,'Risk Register'!$K$2:$K$880,0),"") -> 1
B26: ID | C26: Risk Description | D26: Score | G26: Impact vs Probability | AD26: 4 | AE26: =IFERROR(MATCH(AD26,'Risk Register'!$K$2:$K$880,0),"") -> 5
B27: =IF($AE23="","",INDEX('Risk Register'!$A$2:$A$880,$AE23)) | C27: =IF($AE23="","",INDEX('Risk Register'!$C$2:$C$880,$AE23)) -> D 19 | D27: =IF($AE23="","",INDEX('Risk Register'!$I$2:$I$880,$AE23)) -> 20 | AD27: 5 | AE27: =IFERROR(MATCH(AD27,'Risk Register'!$K$2:$K$880,0),"") -> 6
B28: =IF($AE24="","",INDEX('Risk Register'!$A$2:$A$880,$AE24)) -> 9 | C28: =IF($AE24="","",INDEX('Risk Register'!$C$2:$C$880,$AE24)) -> D 9 | D28: =IF($AE24="","",INDEX('Risk Register'!$I$2:$I$880,$AE24)) -> 10 | AD28: 6 | AE28: =IFERROR(MATCH(AD28,'Risk Register'!$K$2:$K$880,0),"") -> 3 | AN28: settings
B29: =IF($AE25="","",INDEX('Risk Register'!$A$2:$A$880,$AE25)) -> 1 | C29: =IF($AE25="","",INDEX('Risk Register'!$C$2:$C$880,$AE25)) -> D 1 | D29: =IF($AE25="","",INDEX('Risk Register'!$I$2:$I$880,$AE25)) -> 9 | J29: =COUNTIFS('Risk Register'!$H$2:$H$878,$H29,'Risk Register'!$G$2:$G$878,J$27,'Risk Register'!$L$2:$L$878,"<>"&"Closed") -> 0 | K29: =COUNTIFS('Risk Register'!$H$2:$H$878,$H29,'Risk Register'!$G$2:$G$878,K$27,'Risk Register'!$L$2:$L$878,"<>"&"Closed") -> 0 | L29: =COUNTIFS('Risk Register'!$H$2:$H$878,$H29,'Risk Register'!$G$2:$G$878,L$27,'Risk Register'!$L$2:$L$878,"<>"&"Closed") -> 0 | M29: =COUNTIFS('Risk Register'!$H$2:$H$878,$H29,'Risk Register'!$G$2:$G$878,M$27,'Risk Register'!$L$2:$L$878,"<>"&"Closed") -> 0 | N29: =COUNTIFS('Risk Register'!$H$2:$H$878,$H29,'Risk Register'!$G$2:$G$878,N$27,'Risk Register'!$L$2:$L$878,"<>"&"Closed") -> 0 | AD29: 7 | AE29: =IFERROR(MATCH(AD29,'Risk Register'!$K$2:$K$880,0),"") | AH29: =AH$28*$AG29 -> 0 | AI29: =AI$28*$AG29 -> 0 | AJ29: =AJ$28*$AG29 -> 0 | AK29: =AK$28*$AG29 -> 0 | AL29: =AL$28*$AG29 -> 0
B30: =IF($AE26="","",INDEX('Risk Register'!$A$2:$A$880,$AE26)) -> 11 | C30: =IF($AE26="","",INDEX('Risk Register'!$C$2:$C$880,$AE26)) -> D 11 | D30: =IF($AE26="","",INDEX('Risk Register'!$I$2:$I$880,$AE26)) -> 9 | J30: =COUNTIFS('Risk Register'!$H$2:$H$878,$H30,'Risk Register'!$G$2:$G$878,J$27,'Risk Register'!$L$2:$L$878,"<>"&"Closed") -> 0 | K30: =COUNTIFS('Risk Register'!$H$2:$H$878,$H30,'Risk Register'!$G$2:$G$878,K$27,'Risk Register'!$L$2:$L$878,"<>"&"Closed") -> 0 | L30: =COUNTIFS('Risk Register'!$H$2:$H$878,$H30,'Risk Register'!$G$2:$G$878,L$27,'Risk Register'!$L$2:$L$878,"<>"&"Closed") -> 0 | M30: =COUNTIFS('Risk Register'!$H$2:$H$878,$H30,'Risk Register'!$G$2:$G$878,M$27,'Risk Register'!$L$2:$L$878,"<>"&"Closed") -> 0 | N30: =COUNTIFS('Risk Register'!$H$2:$H$878,$H30,'Risk Register'!$G$2:$G$878,N$27,'Risk Register'!$L$2:$L$878,"<>"&"Closed") -> 0 | AD30: 8 | AE30: =IFERROR(MATCH(AD30,'Risk Register'!$K$2:$K$880,0),"") | AH30: =AH$28*$AG30 -> 0 | AI30: =AI$28*$AG30 -> 0 | AJ30: =AJ$28*$AG30 -> 0 | AK30: =AK$28*$AG30 -> 0 | AL30: =AL$28*$AG30 -> 0
B31: =IF($AE27="","",INDEX('Risk Register'!$A$2:$A$880,$AE27)) -> 14 | C31: =IF($AE27="","",INDEX('Risk Register'!$C$2:$C$880,$AE27)) -> D 14 | D31: =IF($AE27="","",INDEX('Risk Register'!$I$2:$I$880,$AE27)) -> 6 | J31: =COUNTIFS('Risk Register'!$H$2:$H$878,$H31,'Risk Register'!$G$2:$G$878,J$27,'Risk Register'!$L$2:$L$878,"<>"&"Closed") -> 0 | K31: =COUNTIFS('Risk Register'!$H$2:$H$878,$H31,'Risk Register'!$G$2:$G$878,K$27,'Risk Register'!$L$2:$L$878,"<>"&"Closed") -> 0 | L31: =COUNTIFS('Risk Register'!$H$2:$H$878,$H31,'Risk Register'!$G$2:$G$878,L$27,'Risk Register'!$L$2:$L$878,"<>"&"Closed") -> 0 | M31: =COUNTIFS('Risk Register'!$H$2:$H$878,$H31,'Risk Register'!$G$2:$G$878,M$27,'Risk Register'!$L$2:$L$878,"<>"&"Closed") -> 0 | N31: =COUNTIFS('Risk Register'!$H$2:$H$878,$H31,'Risk Register'!$G$2:$G$878,N$27,'Risk Register'!$L$2:$L$878,"<>"&"Closed") -> 0 | AH31: =AH$28*$AG31 -> 0 | AI31: =AI$28*$AG31 -> 0 | AJ31: =AJ$28*$AG31 -> 0 | AK31: =AK$28*$AG31 -> 0 | AL31: =AL$28*$AG31 -> 0
B32: =IF($AE28="","",INDEX('Risk Register'!$A$2:$A$880,$AE28)) -> 6 | C32: =IF($AE28="","",INDEX('Risk Register'!$C$2:$C$880,$AE28)) -> D 6 | D32: =IF($AE28="","",INDEX('Risk Register'!$I$2:$I$880,$AE28)) -> 3 | J32: =COUNTIFS('Risk Register'!$H$2:$H$878,$H32,'Risk Register'!$G$2:$G$878,J$27,'Risk Register'!$L$2:$L$878,"<>"&"Closed") -> 0 | K32: =COUNTIFS('Risk Register'!$H$2:$H$878,$H32,'Risk Register'!$G$2:$G$878,K$27,'Risk Register'!$L$2:$L$878,"<>"&"Closed") -> 0 | L32: =COUNTIFS('Risk Register'!$H$2:$H$878,$H32,'Risk Register'!$G$2:$G$878,L$27,'Risk Register'!$L$2:$L$878,"<>"&"Closed") -> 0 | M32: =COUNTIFS('Risk Register'!$H$2:$H$878,$H32,'Risk Register'!$G$2:$G$878,M$27,'Risk Register'!$L$2:$L$878,"<>"&"Closed") -> 0 | N32: =COUNTIFS('Risk Register'!$H$2:$H$878,$H32,'Risk Register'!$G$2:$G$878,N$27,'Risk Register'!$L$2:$L$878,"<>"&"Closed") -> 0 | AH32: =AH$28*$AG32 -> 0 | AI32: =AI$28*$AG32 -> 0 | AJ32: =AJ$28*$AG32 -> 0 | AK32: =AK$28*$AG32 -> 0 | AL32: =AL$28*$AG32 -> 0
B33: =IF($AE29="","",INDEX('Risk Register'!$A$2:$A$880,$AE29)) | C33: =IF($AE29="","",INDEX('Risk Register'!$C$2:$C$880,$AE29)) | D33: =IF($AE29="","",INDEX('Risk Register'!$I$2:$I$880,$AE29)) | J33: =COUNTIFS('Risk Register'!$H$2:$H$878,$H33,'Risk Register'!$G$2:$G$878,J$27,'Risk Register'!$L$2:$L$878,"<>"&"Closed") -> 0 | K33: =COUNTIFS('Risk Register'!$H$2:$H$878,$H33,'Risk Register'!$G$2:$G$878,K$27,'Risk Register'!$L$2:$L$878,"<>"&"Closed") -> 0 | L33: =COUNTIFS('Risk Register'!$H$2:$H$878,$H33,'Risk Register'!$G$2:$G$878,L$27,'Risk Register'!$L$2:$L$878,"<>"&"Closed") -> 0 | M33: =COUNTIFS('Risk Register'!$H$2:$H$878,$H33,'Risk Register'!$G$2:$G$878,M$27,'Risk Register'!$L$2:$L$878,"<>"&"Closed") -> 0 | N33: =COUNTIFS('Risk Register'!$H$2:$H$878,$H33,'Risk Register'!$G$2:$G$878,N$27,'Risk Register'!$L$2:$L$878,"<>"&"Closed") -> 0 | AH33: =AH$28*$AG33 -> 0 | AI33: =AI$28*$AG33 -> 0 | AJ33: =AJ$28*$AG33 -> 0 | AK33: =AK$28*$AG33 -> 0 | AL33: =AL$28*$AG33 -> 0
B34: =IF($AE30="","",INDEX('Risk Register'!$A$2:$A$880,$AE30)) | C34: =IF($AE30="","",INDEX('Risk Register'!$C$2:$C$880,$AE30)) | D34: =IF($AE30="","",INDEX('Risk Register'!$I$2:$I$880,$AE30)) | AH34: PMBOK - 135
AH35: Avoid | AI35: Changing the project plan to eliminate the risk.
AH36: Transfer | AI36: Seek to shift the consequence of risk to a 3rd party together with ownership and response
AH37: Mitigate | AI37: Mitigation seeks to reduce the probability and impact of a risk event to an acceptable threshold. Taking early action to reduce the probability or impact is more effective than trying to repair the consequences after it has occurred.
AH38: Accept | AI38: Indicates that the project team has decided not to change the project plan to deal with a risk or is unable to identify any other suitable response strategy.
AM64: CHECK VALUE | AN64: MAX | AO64: SLICES | AP64: DEGREES | AQ64: X | AR64: Y
AM65: =IFERROR(AVERAGEIF('Risk Register'!$L$2:$L$880,"<>Closed",'Risk Register'!$I$2:$I$880),0) -> 9.5 | AN65: 25 | AO65: 0.05 | AP65: =180-(AM65/AN65)*180 -> 111.6 | AQ65: 0 | AR65: 0 | AT65: Remaining risk | AU65: =AS84+AS83 -> 6
AO66: 0.05 | AQ66: =COS(RADIANS(AP65)) -> -0.36812455 | AR66: =SIN(RADIANS(AP65)) -> 0.92977649 | AT66: Clsoed | AU66: =COUNTIF('Risk Register'!L$2:L$870,"="&"Closed") -> 1
AO67: 0.05
AO68: 0.05
AO69: 0.05
AO70: 0.05
AO71: 0.05
AO72: 0.05
AO73: 0.05
AO74: 0.05
AO75: 0.5
AV76: RISK PRIORITY
AU77: Current Status / Priority | AV77: Critical | AW77: High | AX77: Moderate | AY77: Tolerable | AZ77: Negligible | BA77: Total | BB77: % Of Total
AT78: STATUS | AU78: Closed | AV78: =COUNTIFS('Risk Register'!$J:$J,AV$77,'Risk Register'!$L:$L,$AU78) -> 0 | AW78: =COUNTIFS('Risk Register'!$J:$J,AW$77,'Risk Register'!$L:$L,$AU78) -> 0 | AX78: =COUNTIFS('Risk Register'!$J:$J,AX$77,'Risk Register'!$L:$L,$AU78) -> 1 | AY78: =COUNTIFS('Risk Register'!$J:$J,AY$77,'Risk Register'!$L:$L,$AU78) -> 0 | AZ78: =COUNTIFS('Risk Register'!$J:$J,AZ$77,'Risk Register'!$L:$L,$AU78) -> 0 | BA78: =SUM(AV78:AZ78) -> 1 | BB78: =BA78/BA82 -> 0.14285714
AU79: In-Progress | AV79: =COUNTIFS('Risk Register'!$J:$J,AV$77,'Risk Register'!$L:$L,$AU79) -> 0 | AW79: =COUNTIFS('Risk Register'!$J:$J,AW$77,'Risk Register'!$L:$L,$AU79) -> 0 | AX79: =COUNTIFS('Risk Register'!$J:$J,AX$77,'Risk Register'!$L:$L,$AU79) -> 2 | AY79: =COUNTIFS('Risk Register'!$J:$J,AY$77,'Risk Register'!$L:$L,$AU79) -> 0 | AZ79: =COUNTIFS('Risk Register'!$J:$J,AZ$77,'Risk Register'!$L:$L,$AU79) -> 0 | BA79: =SUM(AV79:AZ79) -> 2 | BB79: =BA79/BA82 -> 0.28571429
AU80: Behind | AV80: =COUNTIFS('Risk Register'!$J:$J,AV$77,'Risk Register'!$L:$L,$AU80) -> 0 | AW80: =COUNTIFS('Risk Register'!$J:$J,AW$77,'Risk Register'!$L:$L,$AU80) -> 1 | AX80: =COUNTIFS('Risk Register'!$J:$J,AX$77,'Risk Register'!$L:$L,$AU80) -> 0 | AY80: =COUNTIFS('Risk Register'!$J:$J,AY$77,'Risk Register'!$L:$L,$AU80) -> 1 | AZ80: =COUNTIFS('Risk Register'!$J:$J,AZ$77,'Risk Register'!$L:$L,$AU80) -> 1 | BA80: =SUM(AV80:AZ80) -> 3 | BB80: =BA80/BA82 -> 0.42857143
AU81: Not Started | AV81: =COUNTIFS('Risk Register'!$J:$J,AV$77,'Risk Register'!$L:$L,$AU81) -> 0 | AW81: =COUNTIFS('Risk Register'!$J:$J,AW$77,'Risk Register'!$L:$L,$AU81) -> 0 | AX81: =COUNTIFS('Risk Register'!$J:$J,AX$77,'Risk Register'!$L:$L,$AU81) -> 1 | AY81: =COUNTIFS('Risk Register'!$J:$J,AY$77,'Risk Register'!$L:$L,$AU81) -> 0 | AZ81: =COUNTIFS('Risk Register'!$J:$J,AZ$77,'Risk Register'!$L:$L,$AU81) -> 0 | BA81: =SUM(AV81:AZ81) -> 1 | BB81: =BA81/BA82 -> 0.14285714
AU82: Total | AV82: =SUM(AV78:AV81) -> 0 | AW82: =SUM(AW78:AW81) -> 1 | AX82: =SUM(AX78:AX81) -> 4 | AY82: =SUM(AY78:AY81) -> 1 | AZ82: =SUM(AZ78:AZ81) -> 1 | BA82: =SUM(AV82:AZ82) -> 7 | BB82: =SUM(BB78:BB81) -> 1
AR83: Not Started | AS83: =BA81 -> 1 | AU83: % of Total | AV83: =AV82/BA82 -> 0 | AW83: =AW82/BA82 -> 0.14285714 | AX83: =AX82/BA82 -> 0.57142857 | AY83: =AY82/BA82 -> 0.14285714 | AZ83: =AZ82/BA82 -> 0.14285714 | BA83: =SUM(AV83:AY83) -> 0.85714286
...

Sheet Risk Register
A1: ID | B1: Helper_Row | C1: Risk Description | D1: Risk Effect on Objectives | E1: Impact Area | F1: Impact Category | G1: Impact Rating | H1: Probability | I1: Risk Score | J1: Risk Priority | K1: Risk Ranking | L1: Status | M1: Risk Owner | N1: Date Raised | O1: Closed Date | P1: Mitigation Strategy | Q1: Risk Response
A2: =IF($B2="","",IF(IFERROR(INDEX('RAID Log'!$1:$1048576,$B2,MATCH("RAID ID",'RAID Log'!$1:$1,0)),"")="","",IFERROR(INDEX('RAID Log'!$1:$1048576,$B2,MATCH("RAID ID",'RAID Log'!$1:$1,0)),""))) -> 1 | B2: =IFERROR(MATCH(ROW()-1,'RAID Log'!$S:$S,0),"") -> 2 | C2: =IF($B2="","",IF(IFERROR(INDEX('RAID Log'!$1:$1048576,$B2,MATCH("Description",'RAID Log'!$1:$1,0)),"")="","",IFERROR(INDEX('RAID Log'!$1:$1048576,$B2,MATCH("Description",'RAID Log'!$1:$1,0)),""))) -> D 1 | D2: =IF($B2="","",IF(IFERROR(INDEX('RAID Log'!$1:$1048576,$B2,MATCH("Impact/Effect of the RAID",'RAID Log'!$1:$1,0)),"")="","",IFERROR(INDEX('RAID Log'!$1:$1048576,$B2,MATCH("Impact/Effect of the RAID",'RAID Log'!$1:$1,0)),""))) -> Impact and Effect 1 | E2: =IF($B2="","",IF(IFERROR(INDEX('RAID Log'!$1:$1048576,$B2,MATCH("Impact Area",'RAID Log'!$1:$1,0)),"")="","",IFERROR(INDEX('RAID Log'!$1:$1048576,$B2,MATCH("Impact Area",'RAID Log'!$1:$1,0)),""))) -> Cost | F2: =IF($B2="","",IF(IFERROR(INDEX('RAID Log'!$1:$1048576,$B2,MATCH("Impact Area",'RAID Log'!$1:$1,0)),"")="","",IFERROR(INDEX('RAID Log'!$1:$1048576,$B2,MATCH("Impact Area",'RAID Log'!$1:$1,0)),""))) -> Cost | G2: =IF($B2="","",IF(IFERROR(INDEX('RAID Log'!$1:$1048576,$B2,MATCH("Impact Rating",'RAID Log'!$1:$1,0)),"")="","",IFERROR(INDEX('RAID Log'!$1:$1048576,$B2,MATCH("Impact Rating",'RAID Log'!$1:$1,0)),""))) -> Moderate | H2: =IF($B2="","",IF(IFERROR(INDEX('RAID Log'!$1:$1048576,$B2,MATCH("Initial Probability",'RAID Log'!$1:$1,0)),"")="","",IFERROR(INDEX('RAID Log'!$1:$1048576,$B2,MATCH("Initial Probability",'RAID Log'!$1:$1,0)),""))) -> Average | I2: =IF($B2="","",(IF($G2="Severe",25,IF($G2="Major",20,IF($G2="Moderate",15,IF($G2="Minor",10,IF($G2="Insignificant",5,0))))))*IF($H2="Very High",1,IF($H2="High",0.8,IF($H2="Average",0.6,IF($H2="Low",0.4,IF($H2="Very Low",0.2,0)))))) -> 9 | J2: =IF($B2="","",IF($I2>20,"Critical",IF($I2>15,"High",IF($I2>8,"Moderate",IF($I2>3,"Tolerable","Negligible"))))) -> Moderate | K2: =IF(OR($B2="",UPPER($L2)="CLOSED"),"",COUNTIFS($L$2:$L$880,"<>Closed",$I$2:$I$880,">"&$I2)+COUNTIFS($L$2:$L$880,"<>Closed",$I$2:$I$880,$I2,$N$2:$N$880,"<"&$N2)+COUNTIFS($L$2:$L$880,"<>Closed",$I$2:$I$880,$I2,$N$2:$N$880,$N2,$B$2:$B$880,"<"&$B2)+1) -> 3 | L2: =IF($B2="","",IF(IFERROR(INDEX('RAID Log'!$1:$1048576,$B2,MATCH("Status",'RAID Log'!$1:$1,0)),"")="","",IFERROR(INDEX('RAID Log'!$1:$1048576,$B2,MATCH("Status",'RAID Log'!$1:$1,0)),""))) -> Not Started | M2: =IF($B2="","",IF(IFERROR(INDEX('RAID Log'!$1:$1048576,$B2,MATCH("RAID Owner",'RAID Log'!$1:$1,0)),"")="","",IFERROR(INDEX('RAID Log'!$1:$1048576,$B2,MATCH("RAID Owner",'RAID Log'!$1:$1,0)),""))) -> Owner 1 | N2: =IF($B2="","",IF(IFERROR(INDEX('RAID Log'!$1:$1048576,$B2,MATCH("Date Raised",'RAID Log'!$1:$1,0)),"")="","",IFERROR(INDEX('RAID Log'!$1:$1048576,$B2,MATCH("Date Raised",'RAID Log'!$1:$1,0)),""))) -> 45992 | O2: =IF($B2="","",IF(IFERROR(INDEX('RAID Log'!$1:$1048576,$B2,MATCH("Closed Date",'RAID Log'!$1:$1,0)),"")="","",IFERROR(INDEX('RAID Log'!$1:$1048576,$B2,MATCH("Closed Date",'RAID Log'!$1:$1,0)),""))) | P2: =IF($B2="","",IF(IFERROR(INDEX('RAID Log'!$1:$1048576,$B2,MATCH("Mitigation Strategy",'RAID Log'!$1:$1,0)),"")="","",IFERROR(INDEX('RAID Log'!$1:$1048576,$B2,MATCH("Mitigation Strategy",'RAID Log'!$1:$1,0)),""))) -> Mitigate | Q2: =IF($B2="","",IF(IFERROR(INDEX('RAID Log'!$1:$1048576,$B2,MATCH("RAID Response/Plan",'RAID Log'!$1:$1,0)),"")="","",IFERROR(INDEX('RAID Log'!$1:$1048576,$B2,MATCH("RAID Response/Plan",'RAID Log'!$1:$1,0)),"")))
A3: =IF($B3="","",IF(IFERROR(INDEX('RAID Log'!$1:$1048576,$B3,MATCH("RAID ID",'RAID Log'!$1:$1,0)),"")="","",IFERROR(INDEX('RAID Log'!$1:$1048576,$B3,MATCH("RAID ID",'RAID Log'!$1:$1,0)),""))) -> 4 | B3: =IFERROR(MATCH(ROW()-1,'RAID Log'!$S:$S,0),"") -> 5 | C3: =IF($B3="","",IF(IFERROR(INDEX('RAID Log'!$1:$1048576,$B3,MATCH("Description",'RAID Log'!$1:$1,0)),"")="","",IFERROR(INDEX('RAID Log'!$1:$1048576,$B3,MATCH("Description",'RAID Log'!$1:$1,0)),""))) -> D 4 | D3: =IF($B3="","",IF(IFERROR(INDEX('RAID Log'!$1:$1048576,$B3,MATCH("Impact/Effect of the RAID",'RAID Log'!$1:$1,0)),"")="","",IFERROR(INDEX('RAID Log'!$1:$1048576,$B3,MATCH("Impact/Effect of the RAID",'RAID Log'!$1:$1,0)),""))) -> Impact and Effect 4 | E3: =IF($B3="","",IF(IFERROR(INDEX('RAID Log'!$1:$1048576,$B3,MATCH("Impact Area",'RAID Log'!$1:$1,0)),"")="","",IFERROR(INDEX('RAID Log'!$1:$1048576,$B3,MATCH("Impact Area",'RAID Log'!$1:$1,0)),""))) -> Security/Compliance | F3: =IF($B3="","",IF(IFERROR(INDEX('RAID Log'!$1:$1048576,$B3,MATCH("Impact Area",'RAID Log'!$1:$1,0)),"")="","",IFERROR(INDEX('RAID Log'!$1:$1048576,$B3,MATCH("Impact Area",'RAID Log'!$1:$1,0)),""))) -> Security/Compliance | G3: =IF($B3="","",IF(IFERROR(INDEX('RAID Log'!$1:$1048576,$B3,MATCH("Impact Rating",'RAID Log'!$1:$1,0)),"")="","",IFERROR(INDEX('RAID Log'!$1:$1048576,$B3,MATCH("Impact Rating",'RAID Log'!$1:$1,0)),""))) -> Minor | H3: =IF($B3="","",IF(IFERROR(INDEX('RAID Log'!$1:$1048576,$B3,MATCH("Initial Probability",'RAID Log'!$1:$1,0)),"")="","",IFERROR(INDEX('RAID Log'!$1:$1048576,$B3,MATCH("Initial Probability",'RAID Log'!$1:$1,0)),""))) -> Very High | I3: =IF($B3="","",(IF($G3="Severe",25,IF($G3="Major",20,IF($G3="Moderate",15,IF($G3="Minor",10,IF($G3="Insignificant",5,0))))))*IF($H3="Very High",1,IF($H3="High",0.8,IF($H3="Average",0.6,IF($H3="Low",0.4,IF($H3="Very Low",0.2,0)))))) -> 10 | J3: =IF($B3="","",IF($I3>20,"Critical",IF($I3>15,"High",IF($I3>8,"Moderate",IF($I3>3,"Tolerable","Negligible"))))) -> Moderate | K3: =IF(OR($B3="",UPPER($L3)="CLOSED"),"",COUNTIFS($L$2:$L$880,"<>Closed",$I$2:$I$880,">"&$I3)+COUNTIFS($L$2:$L$880,"<>Closed",$I$2:$I$880,$I3,$N$2:$N$880,"<"&$N3)+COUNTIFS($L$2:$L$880,"<>Closed",$I$2:$I$880,$I3,$N$2:$N$880,$N3,$B$2:$B$880,"<"&$B3)+1) | L3: =IF($B3="","",IF(IFERROR(INDEX('RAID Log'!$1:$1048576,$B3,MATCH("Status",'RAID Log'!$1:$1,0)),"")="","",IFERROR(INDEX('RAID Log'!$1:$1048576,$B3,MATCH("Status",'RAID Log'!$1:$1,0)),""))) -> Closed | M3: =IF($B3="","",IF(IFERROR(INDEX('RAID Log'!$1:$1048576,$B3,MATCH("RAID Owner",'RAID Log'!$1:$1,0)),"")="","",IFERROR(INDEX('RAID Log'!$1:$1048576,$B3,MATCH("RAID Owner",'RAID Log'!$1:$1,0)),""))) -> Owner 4 | N3: =IF($B3="","",IF(IFERROR(INDEX('RAID Log'!$1:$1048576,$B3,MATCH("Date Raised",'RAID Log'!$1:$1,0)),"")="","",IFERROR(INDEX('RAID Log'!$1:$1048576,$B3,MATCH("Date Raised",'RAID Log'!$1:$1,0)),""))) -> 46039 | O3: =IF($B3="","",IF(IFERROR(INDEX('RAID Log'!$1:$1048576,$B3,MATCH("Closed Date",'RAID Log'!$1:$1,0)),"")="","",IFERROR(INDEX('RAID Log'!$1:$1048576,$B3,MATCH("Closed Date",'RAID Log'!$1:$1,0)),""))) -> 46049 | P3: =IF($B3="","",IF(IFERROR(INDEX('RAID Log'!$1:$1048576,$B3,MATCH("Mitigation Strategy",'RAID Log'!$1:$1,0)),"")="","",IFERROR(INDEX('RAID Log'!$1:$1048576,$B3,MATCH("Mitigation Strategy",'RAID Log'!$1:$1,0)),""))) -> Accept | Q3: =IF($B3="","",IF(IFERROR(INDEX('RAID Log'!$1:$1048576,$B3,MATCH("RAID Response/Plan",'RAID Log'!$1:$1,0)),"")="","",IFERROR(INDEX('RAID Log'!$1:$1048576,$B3,MATCH("RAID Response/Plan",'RAID Log'!$1:$1,0)),"")))
A4: =IF($B4="","",IF(IFERROR(INDEX('RAID Log'!$1:$1048576,$B4,MATCH("RAID ID",'RAID Log'!$1:$1,0)),"")="","",IFERROR(INDEX('RAID Log'!$1:$1048576,$B4,MATCH("RAID ID",'RAID Log'!$1:$1,0)),""))) -> 6 | B4: =IFERROR(MATCH(ROW()-1,'RAID Log'!$S:$S,0),"") -> 7 | C4: =IF($B4="","",IF(IFERROR(INDEX('RAID Log'!$1:$1048576,$B4,MATCH("Description",'RAID Log'!$1:$1,0)),"")="","",IFERROR(INDEX('RAID Log'!$1:$1048576,$B4,MATCH("Description",'RAID Log'!$1:$1,0)),""))) -> D 6 | D4: =IF($B4="","",IF(IFERROR(INDEX('RAID Log'!$1:$1048576,$B4,MATCH("Impact/Effect of the RAID",'RAID Log'!$1:$1,0)),"")="","",IFERROR(INDEX('RAID Log'!$1:$1048576,$B4,MATCH("Impact/Effect of the RAID",'RAID Log'!$1:$1,0)),""))) -> Impact and Effect 6 | E4: =IF($B4="","",IF(IFERROR(INDEX('RAID Log'!$1:$1048576,$B4,MATCH("Impact Area",'RAID Log'!$1:$1,0)),"")="","",IFERROR(INDEX('RAID Log'!$1:$1048576,$B4,MATCH("Impact Area",'RAID Log'!$1:$1,0)),""))) -> Security/Compliance | F4: =IF($B4="","",IF(IFERROR(INDEX('RAID Log'!$1:$1048576,$B4,MATCH("Impact Area",'RAID Log'!$1:$1,0)),"")="","",IFERROR(INDEX('RAID Log'!$1:$1048576,$B4,MATCH("Impact Area",'RAID Log'!$1:$1,0)),""))) -> Security/Compliance | G4: =IF($B4="","",IF(IFERROR(INDEX('RAID Log'!$1:$1048576,$B4,MATCH("Impact Rating",'RAID Log'!$1:$1,0)),"")="","",IFERROR(INDEX('RAID Log'!$1:$1048576,$B4,MATCH("Impact Rating",'RAID Log'!$1:$1,0)),""))) -> Moderate | H4: =IF($B4="","",IF(IFERROR(INDEX('RAID Log'!$1:$1048576,$B4,MATCH("Initial Probability",'RAID Log'!$1:$1,0)),"")="","",IFERROR(INDEX('RAID Log'!$1:$1048576,$B4,MATCH("Initial Probability",'RAID Log'!$1:$1,0)),""))) -> Very Low | I4: =IF($B4="","",(IF($G4="Severe",25,IF($G4="Major",20,IF($G4="Moderate",15,IF($G4="Minor",10,IF($G4="Insignificant",5,0))))))*IF($H4="Very High",1,IF($H4="High",0.8,IF($H4="Average",0.6,IF($H4="Low",0.4,IF($H4="Very Low",0.2,0)))))) -> 3 | J4: =IF($B4="","",IF($I4>20,"Critical",IF($I4>15,"High",IF($I4>8,"Moderate",IF($I4>3,"Tolerable","Negligible"))))) -> Negligible | K4: =IF(OR($B4="",UPPER($L4)="CLOSED"),"",COUNTIFS($L$2:$L$880,"<>Closed",$I$2:$I$880,">"&$I4)+COUNTIFS($L$2:$L$880,"<>Closed",$I$2:$I$880,$I4,$N$2:$N$880,"<"&$N4)+COUNTIFS($L$2:$L$880,"<>Closed",$I$2:$I$880,$I4,$N$2:$N$880,$N4,$B$2:$B$880,"<"&$B4)+1) -> 6 | L4: =IF($B4="","",IF(IFERROR(INDEX('RAID Log'!$1:$1048576,$B4,MATCH("Status",'RAID Log'!$1:$1,0)),"")="","",IFERROR(INDEX('RAID Log'!$1:$1048576,$B4,MATCH("Status",'RAID Log'!$1:$1,0)),""))) -> Behind | M4: =IF($B4="","",IF(IFERROR(INDEX('RAID Log'!$1:$1048576,$B4,MATCH("RAID Owner",'RAID Log'!$1:$1,0)),"")="","",IFERROR(INDEX('RAID Log'!$1:$1048576,$B4,MATCH("RAID Owner",'RAID Log'!$1:$1,0)),""))) -> Owner 6 | N4: =IF($B4="","",IF(IFERROR(INDEX('RAID Log'!$1:$1048576,$B4,MATCH("Date Raised",'RAID Log'!$1:$1,0)),"")="","",IFERROR(INDEX('RAID Log'!$1:$1048576,$B4,MATCH("Date Raised",'RAID Log'!$1:$1,0)),""))) -> 46053 | O4: =IF($B4="","",IF(IFERROR(INDEX('RAID Log'!$1:$1048576,$B4,MATCH("Closed Date",'RAID Log'!$1:$1,0)),"")="","",IFERROR(INDEX('RAID Log'!$1:$1048576,$B4,MATCH("Closed Date",'RAID Log'!$1:$1,0)),""))) | P4: =IF($B4="","",IF(IFERROR(INDEX('RAID Log'!$1:$1048576,$B4,MATCH("Mitigation Strategy",'RAID Log'!$1:$1,0)),"")="","",IFERROR(INDEX('RAID Log'!$1:$1048576,$B4,MATCH("Mitigation Strategy",'RAID Log'!$1:$1,0)),""))) -> Escalate | Q4: =IF($B4="","",IF(IFERROR(INDEX('RAID Log'!$1:$1048576,$B4,MATCH("RAID Response/Plan",'RAID Log'!$1:$1,0)),"")="","",IFERROR(INDEX('RAID Log'!$1:$1048576,$B4,MATCH("RAID Response/Plan",'RAID Log'!$1:$1,0)),"")))
A5: =IF($B5="","",IF(IFERROR(INDEX('RAID Log'!$1:$1048576,$B5,MATCH("RAID ID",'RAID Log'!$1:$1,0)),"")="","",IFERROR(INDEX('RAID Log'!$1:$1048576,$B5,MATCH("RAID ID",'RAID Log'!$1:$1,0)),""))) -> 9 | B5: =IFERROR(MATCH(ROW()-1,'RAID Log'!$S:$S,0),"") -> 10 | C5: =IF($B5="","",IF(IFERROR(INDEX('RAID Log'!$1:$1048576,$B5,MATCH("Description",'RAID Log'!$1:$1,0)),"")="","",IFERROR(INDEX('RAID Log'!$1:$1048576,$B5,MATCH("Description",'RAID Log'!$1:$1,0)),""))) -> D 9 | D5: =IF($B5="","",IF(IFERROR(INDEX('RAID Log'!$1:$1048576,$B5,MATCH("Impact/Effect of the RAID",'RAID Log'!$1:$1,0)),"")="","",IFERROR(INDEX('RAID Log'!$1:$1048576,$B5,MATCH("Impact/Effect of the RAID",'RAID Log'!$1:$1,0)),""))) -> Impact and Effect 9 | E5: =IF($B5="","",IF(IFERROR(INDEX('RAID Log'!$1:$1048576,$B5,MATCH("Impact Area",'RAID Log'!$1:$1,0)),"")="","",IFERROR(INDEX('RAID Log'!$1:$1048576,$B5,MATCH("Impact Area",'RAID Log'!$1:$1,0)),""))) -> Schedule | F5: =IF($B5="","",IF(IFERROR(INDEX('RAID Log'!$1:$1048576,$B5,MATCH("Impact Area",'RAID Log'!$1:$1,0)),"")="","",IFERROR(INDEX('RAID Log'!$1:$1048576,$B5,MATCH("Impact Area",'RAID Log'!$1:$1,0)),""))) -> Schedule | G5: =IF($B5="","",IF(IFERROR(INDEX('RAID Log'!$1:$1048576,$B5,MATCH("Impact Rating",'RAID Log'!$1:$1,0)),"")="","",IFERROR(INDEX('RAID Log'!$1:$1048576,$B5,MATCH("Impact Rating",'RAID Log'!$1:$1,0)),""))) -> Minor | H5: =IF($B5="","",IF(IFERROR(INDEX('RAID Log'!$1:$1048576,$B5,MATCH("Initial Probability",'RAID Log'!$1:$1,0)),"")="","",IFERROR(INDEX('RAID Log'!$1:$1048576,$B5,MATCH("Initial Probability",'RAID Log'!$1:$1,0)),""))) -> Very High | I5: =IF($B5="","",(IF($G5="Severe",25,IF($G5="Major",20,IF($G5="Moderate",15,IF($G5="Minor",10,IF($G5="Insignificant",5,0))))))*IF($H5="Very High",1,IF($H5="High",0.8,IF($H5="Average",0.6,IF($H5="Low",0.4,IF($H5="Very Low",0.2,0)))))) -> 10 | J5: =IF($B5="","",IF($I5>20,"Critical",IF($I5>15,"High",IF($I5>8,"Moderate",IF($I5>3,"Tolerable","Negligible"))))) -> Moderate | K5: =IF(OR($B5="",UPPER($L5)="CLOSED"),"",COUNTIFS($L$2:$L$880,"<>Closed",$I$2:$I$880,">"&$I5)+COUNTIFS($L$2:$L$880,"<>Closed",$I$2:$I$880,$I5,$N$2:$N$880,"<"&$N5)+COUNTIFS($L$2:$L$880,"<>Closed",$I$2:$I$880,$I5,$N$2:$N$880,$N5,$B$2:$B$880,"<"&$B5)+1) -> 2 | L5: =IF($B5="","",IF(IFERROR(INDEX('RAID Log'!$1:$1048576,$B5,MATCH("Status",'RAID Log'!$1:$1,0)),"")="","",IFERROR(INDEX('RAID Log'!$1:$1048576,$B5,MATCH("Status",'RAID Log'!$1:$1,0)),""))) -> In-Progress | M5: =IF($B5="","",IF(IFERROR(INDEX('RAID Log'!$1:$1048576,$B5,MATCH("RAID Owner",'RAID Log'!$1:$1,0)),"")="","",IFERROR(INDEX('RAID Log'!$1:$1048576,$B5,MATCH("RAID Owner",'RAID Log'!$1:$1,0)),""))) -> Owner 9 | N5: =IF($B5="","",IF(IFERROR(INDEX('RAID Log'!$1:$1048576,$B5,MATCH("Date Raised",'RAID Log'!$1:$1,0)),"")="","",IFERROR(INDEX('RAID Log'!$1:$1048576,$B5,MATCH("Date Raised",'RAID Log'!$1:$1,0)),""))) -> 46074 | O5: =IF($B5="","",IF(IFERROR(INDEX('RAID Log'!$1:$1048576,$B5,MATCH("Closed Date",'RAID Log'!$1:$1,0)),"")="","",IFERROR(INDEX('RAID Log'!$1:$1048576,$B5,MATCH("Closed Date",'RAID Log'!$1:$1,0)),""))) | P5: =IF($B5="","",IF(IFERROR(INDEX('RAID Log'!$1:$1048576,$B5,MATCH("Mitigation Strategy",'RAID Log'!$1:$1,0)),"")="","",IFERROR(INDEX('RAID Log'!$1:$1048576,$B5,MATCH("Mitigation Strategy",'RAID Log'!$1:$1,0)),""))) -> Avoid | Q5: =IF($B5="","",IF(IFERROR(INDEX('RAID Log'!$1:$1048576,$B5,MATCH("RAID Response/Plan",'RAID Log'!$1:$1,0)),"")="","",IFERROR(INDEX('RAID Log'!$1:$1048576,$B5,MATCH("RAID Response/Plan",'RAID Log'!$1:$1,0)),"")))
A6: =IF($B6="","",IF(IFERROR(INDEX('RAID Log'!$1:$1048576,$B6,MATCH("RAID ID",'RAID Log'!$1:$1,0)),"")="","",IFERROR(INDEX('RAID Log'!$1:$1048576,$B6,MATCH("RAID ID",'RAID Log'!$1:$1,0)),""))) -> 11 | B6: =IFERROR(MATCH(ROW()-1,'RAID Log'!$S:$S,0),"") -> 12 | C6: =IF($B6="","",IF(IFERROR(INDEX('RAID Log'!$1:$1048576,$B6,MATCH("Description",'RAID Log'!$1:$1,0)),"")="","",IFERROR(INDEX('RAID Log'!$1:$1048576,$B6,MATCH("Description",'RAID Log'!$1:$1,0)),""))) -> D 11 | D6: =IF($B6="","",IF(IFERROR(INDEX('RAID Log'!$1:$1048576,$B6,MATCH("Impact/Effect of the RAID",'RAID Log'!$1:$1,0)),"")="","",IFERROR(INDEX('RAID Log'!$1:$1048576,$B6,MATCH("Impact/Effect of the RAID",'RAID Log'!$1:$1,0)),""))) -> Impact and Effect 11 | E6: =IF($B6="","",IF(IFERROR(INDEX('RAID Log'!$1:$1048576,$B6,MATCH("Impact Area",'RAID Log'!$1:$1,0)),"")="","",IFERROR(INDEX('RAID Log'!$1:$1048576,$B6,MATCH("Impact Area",'RAID Log'!$1:$1,0)),""))) -> Cost | F6: =IF($B6="","",IF(IFERROR(INDEX('RAID Log'!$1:$1048576,$B6,MATCH("Impact Area",'RAID Log'!$1:$1,0)),"")="","",IFERROR(INDEX('RAID Log'!$1:$1048576,$B6,MATCH("Impact Area",'RAID Log'!$1:$1,0)),""))) -> Cost | G6: =IF($B6="","",IF(IFERROR(INDEX('RAID Log'!$1:$1048576,$B6,MATCH("Impact Rating",'RAID Log'!$1:$1,0)),"")="","",IFERROR(INDEX('RAID Log'!$1:$1048576,$B6,MATCH("Impact Rating",'RAID Log'!$1:$1,0)),""))) -> Moderate | H6: =IF($B6="","",IF(IFERROR(INDEX('RAID Log'!$1:$1048576,$B6,MATCH("Initial Probability",'RAID Log'!$1:$1,0)),"")="","",IFERROR(INDEX('RAID Log'!$1:$1048576,$B6,MATCH("Initial Probability",'RAID Log'!$1:$1,0)),""))) -> Average | I6: =IF($B6="","",(IF($G6="Severe",25,IF($G6="Major",20,IF($G6="Moderate",15,IF($G6="Minor",10,IF($G6="Insignificant",5,0))))))*IF($H6="Very High",1,IF($H6="High",0.8,IF($H6="Average",0.6,IF($H6="Low",0.4,IF($H6="Very Low",0.2,0)))))) -> 9 | J6: =IF($B6="","",IF($I6>20,"Critical",IF($I6>15,"High",IF($I6>8,"Moderate",IF($I6>3,"Tolerable","Negligible"))))) -> Moderate | K6: =IF(OR($B6="",UPPER($L6)="CLOSED"),"",COUNTIFS($L$2:$L$880,"<>Closed",$I$2:$I$880,">"&$I6)+COUNTIFS($L$2:$L$880,"<>Closed",$I$2:$I$880,$I6,$N$2:$N$880,"<"&$N6)+COUNTIFS($L$2:$L$880,"<>Closed",$I$2:$I$880,$I6,$N$2:$N$880,$N6,$B$2:$B$880,"<"&$B6)+1) -> 4 | L6: =IF($B6="","",IF(IFERROR(INDEX('RAID Log'!$1:$1048576,$B6,MATCH("Status",'RAID Log'!$1:$1,0)),"")="","",IFERROR(INDEX('RAID Log'!$1:$1048576,$B6,MATCH("Status",'RAID Log'!$1:$1,0)),""))) -> In-Progress | M6: =IF($B6="","",IF(IFERROR(INDEX('RAID Log'!$1:$1048576,$B6,MATCH("RAID Owner",'RAID Log'!$1:$1,0)),"")="","",IFERROR(INDEX('RAID Log'!$1:$1048576,$B6,MATCH("RAID Owner",'RAID Log'!$1:$1,0)),""))) -> Owner 11 | N6: =IF($B6="","",IF(IFERROR(INDEX('RAID Log'!$1:$1048576,$B6,MATCH("Date Raised",'RAID Log'!$1:$1,0)),"")="","",IFERROR(INDEX('RAID Log'!$1:$1048576,$B6,MATCH("Date Raised",'RAID Log'!$1:$1,0)),""))) -> 46046 | O6: =IF($B6="","",IF(IFERROR(INDEX('RAID Log'!$1:$1048576,$B6,MATCH("Closed Date",'RAID Log'!$1:$1,0)),"")="","",IFERROR(INDEX('RAID Log'!$1:$1048576,$B6,MATCH("Closed Date",'RAID Log'!$1:$1,0)),""))) | P6: =IF($B6="","",IF(IFERROR(INDEX('RAID Log'!$1:$1048576,$B6,MATCH("Mitigation Strategy",'RAID Log'!$1:$1,0)),"")="","",IFERROR(INDEX('RAID Log'!$1:$1048576,$B6,MATCH("Mitigation Strategy",'RAID Log'!$1:$1,0)),""))) -> Mitigate | Q6: =IF($B6="","",IF(IFERROR(INDEX('RAID Log'!$1:$1048576,$B6,MATCH("RAID Response/Plan",'RAID Log'!$1:$1,0)),"")="","",IFERROR(INDEX('RAID Log'!$1:$1048576,$B6,MATCH("RAID Response/Plan",'RAID Log'!$1:$1,0)),"")))
A7: =IF($B7="","",IF(IFERROR(INDEX('RAID Log'!$1:$1048576,$B7,MATCH("RAID ID",'RAID Log'!$1:$1,0)),"")="","",IFERROR(INDEX('RAID Log'!$1:$1048576,$B7,MATCH("RAID ID",'RAID Log'!$1:$1,0)),""))) -> 14 | B7: =IFERROR(MATCH(ROW()-1,'RAID Log'!$S:$S,0),"") -> 15 | C7: =IF($B7="","",IF(IFERROR(INDEX('RAID Log'!$1:$1048576,$B7,MATCH("Description",'RAID Log'!$1:$1,0)),"")="","",IFERROR(INDEX('RAID Log'!$1:$1048576,$B7,MATCH("Description",'RAID Log'!$1:$1,0)),""))) -> D 14 | D7: =IF($B7="","",IF(IFERROR(INDEX('RAID Log'!$1:$1048576,$B7,MATCH("Impact/Effect of the RAID",'RAID Log'!$1:$1,0)),"")="","",IFERROR(INDEX('RAID Log'!$1:$1048576,$B7,MATCH("Impact/Effect of the RAID",'RAID Log'!$1:$1,0)),""))) -> Impact and Effect 14 | E7: =IF($B7="","",IF(IFERROR(INDEX('RAID Log'!$1:$1048576,$B7,MATCH("Impact Area",'RAID Log'!$1:$1,0)),"")="","",IFERROR(INDEX('RAID Log'!$1:$1048576,$B7,MATCH("Impact Area",'RAID Log'!$1:$1,0)),""))) -> Other | F7: =IF($B7="","",IF(IFERROR(INDEX('RAID Log'!$1:$1048576,$B7,MATCH("Impact Area",'RAID Log'!$1:$1,0)),"")="","",IFERROR(INDEX('RAID Log'!$1:$1048576,$B7,MATCH("Impact Area",'RAID Log'!$1:$1,0)),""))) -> Other | G7: =IF($B7="","",IF(IFERROR(INDEX('RAID Log'!$1:$1048576,$B7,MATCH("Impact Rating",'RAID Log'!$1:$1,0)),"")="","",IFERROR(INDEX('RAID Log'!$1:$1048576,$B7,MATCH("Impact Rating",'RAID Log'!$1:$1,0)),""))) -> Minor | H7: =IF($B7="","",IF(IFERROR(INDEX('RAID Log'!$1:$1048576,$B7,MATCH("Initial Probability",'RAID Log'!$1:$1,0)),"")="","",IFERROR(INDEX('RAID Log'!$1:$1048576,$B7,MATCH("Initial Probability",'RAID Log'!$1:$1,0)),""))) -> Average | I7: =IF($B7="","",(IF($G7="Severe",25,IF($G7="Major",20,IF($G7="Moderate",15,IF($G7="Minor",10,IF($G7="Insignificant",5,0))))))*IF($H7="Very High",1,IF($H7="High",0.8,IF($H7="Average",0.6,IF($H7="Low",0.4,IF($H7="Very Low",0.2,0)))))) -> 6 | J7: =IF($B7="","",IF($I7>20,"Critical",IF($I7>15,"High",IF($I7>8,"Moderate",IF($I7>3,"Tolerable","Negligible"))))) -> Tolerable | K7: =IF(OR($B7="",UPPER($L7)="CLOSED"),"",COUNTIFS($L$2:$L$880,"<>Closed",$I$2:$I$880,">"&$I7)+COUNTIFS($L$2:$L$880,"<>Closed",$I$2:$I$880,$I7,$N$2:$N$880,"<"&$N7)+COUNTIFS($L$2:$L$880,"<>Closed",$I$2:$I$880,$I7,$N$2:$N$880,$N7,$B$2:$B$880,"<"&$B7)+1) -> 5 | L7: =IF($B7="","",IF(IFERROR(INDEX('RAID Log'!$1:$1048576,$B7,MATCH("Status",'RAID Log'!$1:$1,0)),"")="","",IFERROR(INDEX('RAID Log'!$1:$1048576,$B7,MATCH("Status",'RAID Log'!$1:$1,0)),""))) -> Behind | M7: =IF($B7="","",IF(IFERROR(INDEX('RAID Log'!$1:$1048576,$B7,MATCH("RAID Owner",'RAID Log'!$1:$1,0)),"")="","",IFERROR(INDEX('RAID Log'!$1:$1048576,$B7,MATCH("RAID Owner",'RAID Log'!$1:$1,0)),""))) -> Owner 3 | N7: =IF($B7="","",IF(IFERROR(INDEX('RAID Log'!$1:$1048576,$B7,MATCH("Date Raised",'RAID Log'!$1:$1,0)),"")="","",IFERROR(INDEX('RAID Log'!$1:$1048576,$B7,MATCH("Date Raised",'RAID Log'!$1:$1,0)),""))) -> 46067 | O7: =IF($B7="","",IF(IFERROR(INDEX('RAID Log'!$1:$1048576,$B7,MATCH("Closed Date",'RAID Log'!$1:$1,0)),"")="","",IFERROR(INDEX('RAID Log'!$1:$1048576,$B7,MATCH("Closed Date",'RAID Log'!$1:$1,0)),""))) | P7: =IF($B7="","",IF(IFERROR(INDEX('RAID Log'!$1:$1048576,$B7,MATCH("Mitigation Strategy",'RAID Log'!$1:$1,0)),"")="","",IFERROR(INDEX('RAID Log'!$1:$1048576,$B7,MATCH("Mitigation Strategy",'RAID Log'!$1:$1,0)),""))) -> Transfer | Q7: =IF($B7="","",IF(IFERROR(INDEX('RAID Log'!$1:$1048576,$B7,MATCH("RAID Response/Plan",'RAID Log'!$1:$1,0)),"")="","",IFERROR(INDEX('RAID Log'!$1:$1048576,$B7,MATCH("RAID Response/Plan",'RAID Log'!$1:$1,0)),"")))
A8: =IF($B8="","",IF(IFERROR(INDEX('RAID Log'!$1:$1048576,$B8,MATCH("RAID ID",'RAID Log'!$1:$1,0)),"")="","",IFERROR(INDEX('RAID Log'!$1:$1048576,$B8,MATCH("RAID ID",'RAID Log'!$1:$1,0)),""))) | B8: =IFERROR(MATCH(ROW()-1,'RAID Log'!$S:$S,0),"") -> 20 | C8: =IF($B8="","",IF(IFERROR(INDEX('RAID Log'!$1:$1048576,$B8,MATCH("Description",'RAID Log'!$1:$1,0)),"")="","",IFERROR(INDEX('RAID Log'!$1:$1048576,$B8,MATCH("Description",'RAID Log'!$1:$1,0)),""))) -> D 19 | D8: =IF($B8="","",IF(IFERROR(INDEX('RAID Log'!$1:$1048576,$B8,MATCH("Impact/Effect of the RAID",'RAID Log'!$1:$1,0)),"")="","",IFERROR(INDEX('RAID Log'!$1:$1048576,$B8,MATCH("Impact/Effect of the RAID",'RAID Log'!$1:$1,0)),""))) -> Impact and Effect 19 | E8: =IF($B8="","",IF(IFERROR(INDEX('RAID Log'!$1:$1048576,$B8,MATCH("Impact Area",'RAID Log'!$1:$1,0)),"")="","",IFERROR(INDEX('RAID Log'!$1:$1048576,$B8,MATCH("Impact Area",'RAID Log'!$1:$1,0)),""))) -> Other | F8: =IF($B8="","",IF(IFERROR(INDEX('RAID Log'!$1:$1048576,$B8,MATCH("Impact Area",'RAID Log'!$1:$1,0)),"")="","",IFERROR(INDEX('RAID Log'!$1:$1048576,$B8,MATCH("Impact Area",'RAID Log'!$1:$1,0)),""))) -> Other | G8: =IF($B8="","",IF(IFERROR(INDEX('RAID Log'!$1:$1048576,$B8,MATCH("Impact Rating",'RAID Log'!$1:$1,0)),"")="","",IFERROR(INDEX('RAID Log'!$1:$1048576,$B8,MATCH("Impact Rating",'RAID Log'!$1:$1,0)),""))) -> Major | H8: =IF($B8="","",IF(IFERROR(INDEX('RAID Log'!$1:$1048576,$B8,MATCH("Initial Probability",'RAID Log'!$1:$1,0)),"")="","",IFERROR(INDEX('RAID Log'!$1:$1048576,$B8,MATCH("Initial Probability",'RAID Log'!$1:$1,0)),""))) -> Very High | I8: =IF($B8="","",(IF($G8="Severe",25,IF($G8="Major",20,IF($G8="Moderate",15,IF($G8="Minor",10,IF($G8="Insignificant",5,0))))))*IF($H8="Very High",1,IF($H8="High",0.8,IF($H8="Average",0.6,IF($H8="Low",0.4,IF($H8="Very Low",0.2,0)))))) -> 20 | J8: =IF($B8="","",IF($I8>20,"Critical",IF($I8>15,"High",IF($I8>8,"Moderate",IF($I8>3,"Tolerable","Negligible"))))) -> High | K8: =IF(OR($B8="",UPPER($L8)="CLOSED"),"",COUNTIFS($L$2:$L$880,"<>Closed",$I$2:$I$880,">"&$I8)+COUNTIFS($L$2:$L$880,"<>Closed",$I$2:$I$880,$I8,$N$2:$N$880,"<"&$N8)+COUNTIFS($L$2:$L$880,"<>Closed",$I$2:$I$880,$I8,$N$2:$N$880,$N8,$B$2:$B$880,"<"&$B8)+1) -> 1 | L8: =IF($B8="","",IF(IFERROR(INDEX('RAID Log'!$1:$1048576,$B8,MATCH("Status",'RAID Log'!$1:$1,0)),"")="","",IFERROR(INDEX('RAID Log'!$1:$1048576,$B8,MATCH("Status",'RAID Log'!$1:$1,0)),""))) -> Behind | M8: =IF($B8="","",IF(IFERROR(INDEX('RAID Log'!$1:$1048576,$B8,MATCH("RAID Owner",'RAID Log'!$1:$1,0)),"")="","",IFERROR(INDEX('RAID Log'!$1:$1048576,$B8,MATCH("RAID Owner",'RAID Log'!$1:$1,0)),""))) -> Owner 8 | N8: =IF($B8="","",IF(IFERROR(INDEX('RAID Log'!$1:$1048576,$B8,MATCH("Date Raised",'RAID Log'!$1:$1,0)),"")="","",IFERROR(INDEX('RAID Log'!$1:$1048576,$B8,MATCH("Date Raised",'RAID Log'!$1:$1,0)),""))) -> 46081 | O8: =IF($B8="","",IF(IFERROR(INDEX('RAID Log'!$1:$1048576,$B8,MATCH("Closed Date",'RAID Log'!$1:$1,0)),"")="","",IFERROR(INDEX('RAID Log'!$1:$1048576,$B8,MATCH("Closed Date",'RAID Log'!$1:$1,0)),""))) | P8: =IF($B8="","",IF(IFERROR(INDEX('RAID Log'!$1:$1048576,$B8,MATCH("Mitigation Strategy",'RAID Log'!$1:$1,0)),"")="","",IFERROR(INDEX('RAID Log'!$1:$1048576,$B8,MATCH("Mitigation Strategy",'RAID Log'!$1:$1,0)),""))) -> Accept | Q8: =IF($B8="","",IF(IFERROR(INDEX('RAID Log'!$1:$1048576,$B8,MATCH("RAID Response/Plan",'RAID Log'!$1:$1,0)),"")="","",IFERROR(INDEX('RAID Log'!$1:$1048576,$B8,MATCH("RAID Response/Plan",'RAID Log'!$1:$1,0)),"")))
A9: =IF($B9="","",IF(IFERROR(INDEX('RAID Log'!$1:$1048576,$B9,MATCH("RAID ID",'RAID Log'!$1:$1,0)),"")="","",IFERROR(INDEX('RAID Log'!$1:$1048576,$B9,MATCH("RAID ID",'RAID Log'!$1:$1,0)),""))) | B9: =IFERROR(MATCH(ROW()-1,'RAID Log'!$S:$S,0),"") | C9: =IF($B9="","",IF(IFERROR(INDEX('RAID Log'!$1:$1048576,$B9,MATCH("Description",'RAID Log'!$1:$1,0)),"")="","",IFERROR(INDEX('RAID Log'!$1:$1048576,$B9,MATCH("Description",'RAID Log'!$1:$1,0)),""))) | D9: =IF($B9="","",IF(IFERROR(INDEX('RAID Log'!$1:$1048576,$B9,MATCH("Impact/Effect of the RAID",'RAID Log'!$1:$1,0)),"")="","",IFERROR(INDEX('RAID Log'!$1:$1048576,$B9,MATCH("Impact/Effect of the RAID",'RAID Log'!$1:$1,0)),""))) | E9: =IF($B9="","",IF(IFERROR(INDEX('RAID Log'!$1:$1048576,$B9,MATCH("Impact Area",'RAID Log'!$1:$1,0)),"")="","",IFERROR(INDEX('RAID Log'!$1:$1048576,$B9,MATCH("Impact Area",'RAID Log'!$1:$1,0)),""))) | F9: =IF($B9="","",IF(IFERROR(INDEX('RAID Log'!$1:$1048576,$B9,MATCH("Impact Area",'RAID Log'!$1:$1,0)),"")="","",IFERROR(INDEX('RAID Log'!$1:$1048576,$B9,MATCH("Impact Area",'RAID Log'!$1:$1,0)),""))) | G9: =IF($B9="","",IF(IFERROR(INDEX('RAID Log'!$1:$1048576,$B9,MATCH("Impact Rating",'RAID Log'!$1:$1,0)),"")="","",IFERROR(INDEX('RAID Log'!$1:$1048576,$B9,MATCH("Impact Rating",'RAID Log'!$1:$1,0)),""))) | H9: =IF($B9="","",IF(IFERROR(INDEX('RAID Log'!$1:$1048576,$B9,MATCH("Initial Probability",'RAID Log'!$1:$1,0)),"")="","",IFERROR(INDEX('RAID Log'!$1:$1048576,$B9,MATCH("Initial Probability",'RAID Log'!$1:$1,0)),""))) | I9: =IF($B9="","",(IF($G9="Severe",25,IF($G9="Major",20,IF($G9="Moderate",15,IF($G9="Minor",10,IF($G9="Insignificant",5,0))))))*IF($H9="Very High",1,IF($H9="High",0.8,IF($H9="Average",0.6,IF($H9="Low",0.4,IF($H9="Very Low",0.2,0)))))) | J9: =IF($B9="","",IF($I9>20,"Critical",IF($I9>15,"High",IF($I9>8,"Moderate",IF($I9>3,"Tolerable","Negligible"))))) | K9: =IF(OR($B9="",UPPER($L9)="CLOSED"),"",COUNTIFS($L$2:$L$880,"<>Closed",$I$2:$I$880,">"&$I9)+COUNTIFS($L$2:$L$880,"<>Closed",$I$2:$I$880,$I9,$N$2:$N$880,"<"&$N9)+COUNTIFS($L$2:$L$880,"<>Closed",$I$2:$I$880,$I9,$N$2:$N$880,$N9,$B$2:$B$880,"<"&$B9)+1) | L9: =IF($B9="","",IF(IFERROR(INDEX('RAID Log'!$1:$1048576,$B9,MATCH("Status",'RAID Log'!$1:$1,0)),"")="","",IFERROR(INDEX('RAID Log'!$1:$1048576,$B9,MATCH("Status",'RAID Log'!$1:$1,0)),""))) | M9: =IF($B9="","",IF(IFERROR(INDEX('RAID Log'!$1:$1048576,$B9,MATCH("RAID Owner",'RAID Log'!$1:$1,0)),"")="","",IFERROR(INDEX('RAID Log'!$1:$1048576,$B9,MATCH("RAID Owner",'RAID Log'!$1:$1,0)),""))) | N9: =IF($B9="","",IF(IFERROR(INDEX('RAID Log'!$1:$1048576,$B9,MATCH("Date Raised",'RAID Log'!$1:$1,0)),"")="","",IFERROR(INDEX('RAID Log'!$1:$1048576,$B9,MATCH("Date Raised",'RAID Log'!$1:$1,0)),""))) | O9: =IF($B9="","",IF(IFERROR(INDEX('RAID Log'!$1:$1048576,$B9,MATCH("Closed Date",'RAID Log'!$1:$1,0)),"")="","",IFERROR(INDEX('RAID Log'!$1:$1048576,$B9,MATCH("Closed Date",'RAID Log'!$1:$1,0)),""))) | P9: =IF($B9="","",IF(IFERROR(INDEX('RAID Log'!$1:$1048576,$B9,MATCH("Mitigation Strategy",'RAID Log'!$1:$1,0)),"")="","",IFERROR(INDEX('RAID Log'!$1:$1048576,$B9,MATCH("Mitigation Strategy",'RAID Log'!$1:$1,0)),""))) | Q9: =IF($B9="","",IF(IFERROR(INDEX('RAID Log'!$1:$1048576,$B9,MATCH("RAID Response/Plan",'RAID Log'!$1:$1,0)),"")="","",IFERROR(INDEX('RAID Log'!$1:$1048576,$B9,MATCH("RAID Response/Plan",'RAID Log'!$1:$1,0)),"")))
A10: =IF($B10="","",IF(IFERROR(INDEX('RAID Log'!$1:$1048576,$B10,MATCH("RAID ID",'RAID Log'!$1:$1,0)),"")="","",IFERROR(INDEX('RAID Log'!$1:$1048576,$B10,MATCH("RAID ID",'RAID Log'!$1:$1,0)),""))) | B10: =IFERROR(MATCH(ROW()-1,'RAID Log'!$S:$S,0),"") | C10: =IF($B10="","",IF(IFERROR(INDEX('RAID Log'!$1:$1048576,$B10,MATCH("Description",'RAID Log'!$1:$1,0)),"")="","",IFERROR(INDEX('RAID Log'!$1:$1048576,$B10,MATCH("Description",'RAID Log'!$1:$1,0)),""))) | D10: =IF($B10="","",IF(IFERROR(INDEX('RAID Log'!$1:$1048576,$B10,MATCH("Impact/Effect of the RAID",'RAID Log'!$1:$1,0)),"")="","",IFERROR(INDEX('RAID Log'!$1:$1048576,$B10,MATCH("Impact/Effect of the RAID",'RAID Log'!$1:$1,0)),""))) | E10: =IF($B10="","",IF(IFERROR(INDEX('RAID Log'!$1:$1048576,$B10,MATCH("Impact Area",'RAID Log'!$1:$1,0)),"")="","",IFERROR(INDEX('RAID Log'!$1:$1048576,$B10,MATCH("Impact Area",'RAID Log'!$1:$1,0)),""))) | F10: =IF($B10="","",IF(IFERROR(INDEX('RAID Log'!$1:$1048576,$B10,MATCH("Impact Area",'RAID Log'!$1:$1,0)),"")="","",IFERROR(INDEX('RAID Log'!$1:$1048576,$B10,MATCH("Impact Area",'RAID Log'!$1:$1,0)),""))) | G10: =IF($B10="","",IF(IFERROR(INDEX('RAID Log'!$1:$1048576,$B10,MATCH("Impact Rating",'RAID Log'!$1:$1,0)),"")="","",IFERROR(INDEX('RAID Log'!$1:$1048576,$B10,MATCH("Impact Rating",'RAID Log'!$1:$1,0)),""))) | H10: =IF($B10="","",IF(IFERROR(INDEX('RAID Log'!$1:$1048576,$B10,MATCH("Initial Probability",'RAID Log'!$1:$1,0)),"")="","",IFERROR(INDEX('RAID Log'!$1:$1048576,$B10,MATCH("Initial Probability",'RAID Log'!$1:$1,0)),""))) | I10: =IF($B10="","",(IF($G10="Severe",25,IF($G10="Major",20,IF($G10="Moderate",15,IF($G10="Minor",10,IF($G10="Insignificant",5,0))))))*IF($H10="Very High",1,IF($H10="High",0.8,IF($H10="Average",0.6,IF($H10="Low",0.4,IF($H10="Very Low",0.2,0)))))) | J10: =IF($B10="","",IF($I10>20,"Critical",IF($I10>15,"High",IF($I10>8,"Moderate",IF($I10>3,"Tolerable","Negligible"))))) | K10: =IF(OR($B10="",UPPER($L10)="CLOSED"),"",COUNTIFS($L$2:$L$880,"<>Closed",$I$2:$I$880,">"&$I10)+COUNTIFS($L$2:$L$880,"<>Closed",$I$2:$I$880,$I10,$N$2:$N$880,"<"&$N10)+COUNTIFS($L$2:$L$880,"<>Closed",$I$2:$I$880,$I10,$N$2:$N$880,$N10,$B$2:$B$880,"<"&$B10)+1) | L10: =IF($B10="","",IF(IFERROR(INDEX('RAID Log'!$1:$1048576,$B10,MATCH("Status",'RAID Log'!$1:$1,0)),"")="","",IFERROR(INDEX('RAID Log'!$1:$1048576,$B10,MATCH("Status",'RAID Log'!$1:$1,0)),""))) | M10: =IF($B10="","",IF(IFERROR(INDEX('RAID Log'!$1:$1048576,$B10,MATCH("RAID Owner",'RAID Log'!$1:$1,0)),"")="","",IFERROR(INDEX('RAID Log'!$1:$1048576,$B10,MATCH("RAID Owner",'RAID Log'!$1:$1,0)),""))) | N10: =IF($B10="","",IF(IFERROR(INDEX('RAID Log'!$1:$1048576,$B10,MATCH("Date Raised",'RAID Log'!$1:$1,0)),"")="","",IFERROR(INDEX('RAID Log'!$1:$1048576,$B10,MATCH("Date Raised",'RAID Log'!$1:$1,0)),""))) | O10: =IF($B10="","",IF(IFERROR(INDEX('RAID Log'!$1:$1048576,$B10,MATCH("Closed Date",'RAID Log'!$1:$1,0)),"")="","",IFERROR(INDEX('RAID Log'!$1:$1048576,$B10,MATCH("Closed Date",'RAID Log'!$1:$1,0)),""))) | P10: =IF($B10="","",IF(IFERROR(INDEX('RAID Log'!$1:$1048576,$B10,MATCH("Mitigation Strategy",'RAID Log'!$1:$1,0)),"")="","",IFERROR(INDEX('RAID Log'!$1:$1048576,$B10,MATCH("Mitigation Strategy",'RAID Log'!$1:$1,0)),""))) | Q10: =IF($B10="","",IF(IFERROR(INDEX('RAID Log'!$1:$1048576,$B10,MATCH("RAID Response/Plan",'RAID Log'!$1:$1,0)),"")="","",IFERROR(INDEX('RAID Log'!$1:$1048576,$B10,MATCH("RAID Response/Plan",'RAID Log'!$1:$1,0)),"")))
A11: =IF($B11="","",IF(IFERROR(INDEX('RAID Log'!$1:$1048576,$B11,MATCH("RAID ID",'RAID Log'!$1:$1,0)),"")="","",IFERROR(INDEX('RAID Log'!$1:$1048576,$B11,MATCH("RAID ID",'RAID Log'!$1:$1,0)),""))) | B11: =IFERROR(MATCH(ROW()-1,'RAID Log'!$S:$S,0),"") | C11: =IF($B11="","",IF(IFERROR(INDEX('RAID Log'!$1:$1048576,$B11,MATCH("Description",'RAID Log'!$1:$1,0)),"")="","",IFERROR(INDEX('RAID Log'!$1:$1048576,$B11,MATCH("Description",'RAID Log'!$1:$1,0)),""))) | D11: =IF($B11="","",IF(IFERROR(INDEX('RAID Log'!$1:$1048576,$B11,MATCH("Impact/Effect of the RAID",'RAID Log'!$1:$1,0)),"")="","",IFERROR(INDEX('RAID Log'!$1:$1048576,$B11,MATCH("Impact/Effect of the RAID",'RAID Log'!$1:$1,0)),""))) | E11: =IF($B11="","",IF(IFERROR(INDEX('RAID Log'!$1:$1048576,$B11,MATCH("Impact Area",'RAID Log'!$1:$1,0)),"")="","",IFERROR(INDEX('RAID Log'!$1:$1048576,$B11,MATCH("Impact Area",'RAID Log'!$1:$1,0)),""))) | F11: =IF($B11="","",IF(IFERROR(INDEX('RAID Log'!$1:$1048576,$B11,MATCH("Impact Area",'RAID Log'!$1:$1,0)),"")="","",IFERROR(INDEX('RAID Log'!$1:$1048576,$B11,MATCH("Impact Area",'RAID Log'!$1:$1,0)),""))) | G11: =IF($B11="","",IF(IFERROR(INDEX('RAID Log'!$1:$1048576,$B11,MATCH("Impact Rating",'RAID Log'!$1:$1,0)),"")="","",IFERROR(INDEX('RAID Log'!$1:$1048576,$B11,MATCH("Impact Rating",'RAID Log'!$1:$1,0)),""))) | H11: =IF($B11="","",IF(IFERROR(INDEX('RAID Log'!$1:$1048576,$B11,MATCH("Initial Probability",'RAID Log'!$1:$1,0)),"")="","",IFERROR(INDEX('RAID Log'!$1:$1048576,$B11,MATCH("Initial Probability",'RAID Log'!$1:$1,0)),""))) | I11: =IF($B11="","",(IF($G11="Severe",25,IF($G11="Major",20,IF($G11="Moderate",15,IF($G11="Minor",10,IF($G11="Insignificant",5,0))))))*IF($H11="Very High",1,IF($H11="High",0.8,IF($H11="Average",0.6,IF($H11="Low",0.4,IF($H11="Very Low",0.2,0)))))) | J11: =IF($B11="","",IF($I11>20,"Critical",IF($I11>15,"High",IF($I11>8,"Moderate",IF($I11>3,"Tolerable","Negligible"))))) | K11: =IF(OR($B11="",UPPER($L11)="CLOSED"),"",COUNTIFS($L$2:$L$880,"<>Closed",$I$2:$I$880,">"&$I11)+COUNTIFS($L$2:$L$880,"<>Closed",$I$2:$I$880,$I11,$N$2:$N$880,"<"&$N11)+COUNTIFS($L$2:$L$880,"<>Closed",$I$2:$I$880,$I11,$N$2:$N$880,$N11,$B$2:$B$880,"<"&$B11)+1) | L11: =IF($B11="","",IF(IFERROR(INDEX('RAID Log'!$1:$1048576,$B11,MATCH("Status",'RAID Log'!$1:$1,0)),"")="","",IFERROR(INDEX('RAID Log'!$1:$1048576,$B11,MATCH("Status",'RAID Log'!$1:$1,0)),""))) | M11: =IF($B11="","",IF(IFERROR(INDEX('RAID Log'!$1:$1048576,$B11,MATCH("RAID Owner",'RAID Log'!$1:$1,0)),"")="","",IFERROR(INDEX('RAID Log'!$1:$1048576,$B11,MATCH("RAID Owner",'RAID Log'!$1:$1,0)),""))) | N11: =IF($B11="","",IF(IFERROR(INDEX('RAID Log'!$1:$1048576,$B11,MATCH("Date Raised",'RAID Log'!$1:$1,0)),"")="","",IFERROR(INDEX('RAID Log'!$1:$1048576,$B11,MATCH("Date Raised",'RAID Log'!$1:$1,0)),""))) | O11: =IF($B11="","",IF(IFERROR(INDEX('RAID Log'!$1:$1048576,$B11,MATCH("Closed Date",'RAID Log'!$1:$1,0)),"")="","",IFERROR(INDEX('RAID Log'!$1:$1048576,$B11,MATCH("Closed Date",'RAID Log'!$1:$1,0)),""))) | P11: =IF($B11="","",IF(IFERROR(INDEX('RAID Log'!$1:$1048576,$B11,MATCH("Mitigation Strategy",'RAID Log'!$1:$1,0)),"")="","",IFERROR(INDEX('RAID Log'!$1:$1048576,$B11,MATCH("Mitigation Strategy",'RAID Log'!$1:$1,0)),""))) | Q11: =IF($B11="","",IF(IFERROR(INDEX('RAID Log'!$1:$1048576,$B11,MATCH("RAID Response/Plan",'RAID Log'!$1:$1,0)),"")="","",IFERROR(INDEX('RAID Log'!$1:$1048576,$B11,MATCH("RAID Response/Plan",'RAID Log'!$1:$1,0)),"")))
A12: =IF($B12="","",IF(IFERROR(INDEX('RAID Log'!$1:$1048576,$B12,MATCH("RAID ID",'RAID Log'!$1:$1,0)),"")="","",IFERROR(INDEX('RAID Log'!$1:$1048576,$B12,MATCH("RAID ID",'RAID Log'!$1:$1,0)),""))) | B12: =IFERROR(MATCH(ROW()-1,'RAID Log'!$S:$S,0),"") | C12: =IF($B12="","",IF(IFERROR(INDEX('RAID Log'!$1:$1048576,$B12,MATCH("Description",'RAID Log'!$1:$1,0)),"")="","",IFERROR(INDEX('RAID Log'!$1:$1048576,$B12,MATCH("Description",'RAID Log'!$1:$1,0)),""))) | D12: =IF($B12="","",IF(IFERROR(INDEX('RAID Log'!$1:$1048576,$B12,MATCH("Impact/Effect of the RAID",'RAID Log'!$1:$1,0)),"")="","",IFERROR(INDEX('RAID Log'!$1:$1048576,$B12,MATCH("Impact/Effect of the RAID",'RAID Log'!$1:$1,0)),""))) | E12: =IF($B12="","",IF(IFERROR(INDEX('RAID Log'!$1:$1048576,$B12,MATCH("Impact Area",'RAID Log'!$1:$1,0)),"")="","",IFERROR(INDEX('RAID Log'!$1:$1048576,$B12,MATCH("Impact Area",'RAID Log'!$1:$1,0)),""))) | F12: =IF($B12="","",IF(IFERROR(INDEX('RAID Log'!$1:$1048576,$B12,MATCH("Impact Area",'RAID Log'!$1:$1,0)),"")="","",IFERROR(INDEX('RAID Log'!$1:$1048576,$B12,MATCH("Impact Area",'RAID Log'!$1:$1,0)),""))) | G12: =IF($B12="","",IF(IFERROR(INDEX('RAID Log'!$1:$1048576,$B12,MATCH("Impact Rating",'RAID Log'!$1:$1,0)),"")="","",IFERROR(INDEX('RAID Log'!$1:$1048576,$B12,MATCH("Impact Rating",'RAID Log'!$1:$1,0)),""))) | H12: =IF($B12="","",IF(IFERROR(INDEX('RAID Log'!$1:$1048576,$B12,MATCH("Initial Probability",'RAID Log'!$1:$1,0)),"")="","",IFERROR(INDEX('RAID Log'!$1:$1048576,$B12,MATCH("Initial Probability",'RAID Log'!$1:$1,0)),""))) | I12: =IF($B12="","",(IF($G12="Severe",25,IF($G12="Major",20,IF($G12="Moderate",15,IF($G12="Minor",10,IF($G12="Insignificant",5,0))))))*IF($H12="Very High",1,IF($H12="High",0.8,IF($H12="Average",0.6,IF($H12="Low",0.4,IF($H12="Very Low",0.2,0)))))) | J12: =IF($B12="","",IF($I12>20,"Critical",IF($I12>15,"High",IF($I12>8,"Moderate",IF($I12>3,"Tolerable","Negligible"))))) | K12: =IF(OR($B12="",UPPER($L12)="CLOSED"),"",COUNTIFS($L$2:$L$880,"<>Closed",$I$2:$I$880,">"&$I12)+COUNTIFS($L$2:$L$880,"<>Closed",$I$2:$I$880,$I12,$N$2:$N$880,"<"&$N12)+COUNTIFS($L$2:$L$880,"<>Closed",$I$2:$I$880,$I12,$N$2:$N$880,$N12,$B$2:$B$880,"<"&$B12)+1) | L12: =IF($B12="","",IF(IFERROR(INDEX('RAID Log'!$1:$1048576,$B12,MATCH("Status",'RAID Log'!$1:$1,0)),"")="","",IFERROR(INDEX('RAID Log'!$1:$1048576,$B12,MATCH("Status",'RAID Log'!$1:$1,0)),""))) | M12: =IF($B12="","",IF(IFERROR(INDEX('RAID Log'!$1:$1048576,$B12,MATCH("RAID Owner",'RAID Log'!$1:$1,0)),"")="","",IFERROR(INDEX('RAID Log'!$1:$1048576,$B12,MATCH("RAID Owner",'RAID Log'!$1:$1,0)),""))) | N12: =IF($B12="","",IF(IFERROR(INDEX('RAID Log'!$1:$1048576,$B12,MATCH("Date Raised",'RAID Log'!$1:$1,0)),"")="","",IFERROR(INDEX('RAID Log'!$1:$1048576,$B12,MATCH("Date Raised",'RAID Log'!$1:$1,0)),""))) | O12: =IF($B12="","",IF(IFERROR(INDEX('RAID Log'!$1:$1048576,$B12,MATCH("Closed Date",'RAID Log'!$1:$1,0)),"")="","",IFERROR(INDEX('RAID Log'!$1:$1048576,$B12,MATCH("Closed Date",'RAID Log'!$1:$1,0)),""))) | P12: =IF($B12="","",IF(IFERROR(INDEX('RAID Log'!$1:$1048576,$B12,MATCH("Mitigation Strategy",'RAID Log'!$1:$1,0)),"")="","",IFERROR(INDEX('RAID Log'!$1:$1048576,$B12,MATCH("Mitigation Strategy",'RAID Log'!$1:$1,0)),""))) | Q12: =IF($B12="","",IF(IFERROR(INDEX('RAID Log'!$1:$1048576,$B12,MATCH("RAID Response/Plan",'RAID Log'!$1:$1,0)),"")="","",IFERROR(INDEX('RAID Log'!$1:$1048576,$B12,MATCH("RAID Response/Plan",'RAID Log'!$1:$1,0)),"")))
A13: =IF($B13="","",IF(IFERROR(INDEX('RAID Log'!$1:$1048576,$B13,MATCH("RAID ID",'RAID Log'!$1:$1,0)),"")="","",IFERROR(INDEX('RAID Log'!$1:$1048576,$B13,MATCH("RAID ID",'RAID Log'!$1:$1,0)),""))) | B13: =IFERROR(MATCH(ROW()-1,'RAID Log'!$S:$S,0),"") | C13: =IF($B13="","",IF(IFERROR(INDEX('RAID Log'!$1:$1048576,$B13,MATCH("Description",'RAID Log'!$1:$1,0)),"")="","",IFERROR(INDEX('RAID Log'!$1:$1048576,$B13,MATCH("Description",'RAID Log'!$1:$1,0)),""))) | D13: =IF($B13="","",IF(IFERROR(INDEX('RAID Log'!$1:$1048576,$B13,MATCH("Impact/Effect of the RAID",'RAID Log'!$1:$1,0)),"")="","",IFERROR(INDEX('RAID Log'!$1:$1048576,$B13,MATCH("Impact/Effect of the RAID",'RAID Log'!$1:$1,0)),""))) | E13: =IF($B13="","",IF(IFERROR(INDEX('RAID Log'!$1:$1048576,$B13,MATCH("Impact Area",'RAID Log'!$1:$1,0)),"")="","",IFERROR(INDEX('RAID Log'!$1:$1048576,$B13,MATCH("Impact Area",'RAID Log'!$1:$1,0)),""))) | F13: =IF($B13="","",IF(IFERROR(INDEX('RAID Log'!$1:$1048576,$B13,MATCH("Impact Area",'RAID Log'!$1:$1,0)),"")="","",IFERROR(INDEX('RAID Log'!$1:$1048576,$B13,MATCH("Impact Area",'RAID Log'!$1:$1,0)),""))) | G13: =IF($B13="","",IF(IFERROR(INDEX('RAID Log'!$1:$1048576,$B13,MATCH("Impact Rating",'RAID Log'!$1:$1,0)),"")="","",IFERROR(INDEX('RAID Log'!$1:$1048576,$B13,MATCH("Impact Rating",'RAID Log'!$1:$1,0)),""))) | H13: =IF($B13="","",IF(IFERROR(INDEX('RAID Log'!$1:$1048576,$B13,MATCH("Initial Probability",'RAID Log'!$1:$1,0)),"")="","",IFERROR(INDEX('RAID Log'!$1:$1048576,$B13,MATCH("Initial Probability",'RAID Log'!$1:$1,0)),""))) | I13: =IF($B13="","",(IF($G13="Severe",25,IF($G13="Major",20,IF($G13="Moderate",15,IF($G13="Minor",10,IF($G13="Insignificant",5,0))))))*IF($H13="Very High",1,IF($H13="High",0.8,IF($H13="Average",0.6,IF($H13="Low",0.4,IF($H13="Very Low",0.2,0)))))) | J13: =IF($B13="","",IF($I13>20,"Critical",IF($I13>15,"High",IF($I13>8,"Moderate",IF($I13>3,"Tolerable","Negligible"))))) | K13: =IF(OR($B13="",UPPER($L13)="CLOSED"),"",COUNTIFS($L$2:$L$880,"<>Closed",$I$2:$I$880,">"&$I13)+COUNTIFS($L$2:$L$880,"<>Closed",$I$2:$I$880,$I13,$N$2:$N$880,"<"&$N13)+COUNTIFS($L$2:$L$880,"<>Closed",$I$2:$I$880,$I13,$N$2:$N$880,$N13,$B$2:$B$880,"<"&$B13)+1) | L13: =IF($B13="","",IF(IFERROR(INDEX('RAID Log'!$1:$1048576,$B13,MATCH("Status",'RAID Log'!$1:$1,0)),"")="","",IFERROR(INDEX('RAID Log'!$1:$1048576,$B13,MATCH("Status",'RAID Log'!$1:$1,0)),""))) | M13: =IF($B13="","",IF(IFERROR(INDEX('RAID Log'!$1:$1048576,$B13,MATCH("RAID Owner",'RAID Log'!$1:$1,0)),"")="","",IFERROR(INDEX('RAID Log'!$1:$1048576,$B13,MATCH("RAID Owner",'RAID Log'!$1:$1,0)),""))) | N13: =IF($B13="","",IF(IFERROR(INDEX('RAID Log'!$1:$1048576,$B13,MATCH("Date Raised",'RAID Log'!$1:$1,0)),"")="","",IFERROR(INDEX('RAID Log'!$1:$1048576,$B13,MATCH("Date Raised",'RAID Log'!$1:$1,0)),""))) | O13: =IF($B13="","",IF(IFERROR(INDEX('RAID Log'!$1:$1048576,$B13,MATCH("Closed Date",'RAID Log'!$1:$1,0)),"")="","",IFERROR(INDEX('RAID Log'!$1:$1048576,$B13,MATCH("Closed Date",'RAID Log'!$1:$1,0)),""))) | P13: =IF($B13="","",IF(IFERROR(INDEX('RAID Log'!$1:$1048576,$B13,MATCH("Mitigation Strategy",'RAID Log'!$1:$1,0)),"")="","",IFERROR(INDEX('RAID Log'!$1:$1048576,$B13,MATCH("Mitigation Strategy",'RAID Log'!$1:$1,0)),""))) | Q13: =IF($B13="","",IF(IFERROR(INDEX('RAID Log'!$1:$1048576,$B13,MATCH("RAID Response/Plan",'RAID Log'!$1:$1,0)),"")="","",IFERROR(INDEX('RAID Log'!$1:$1048576,$B13,MATCH("RAID Response/Plan",'RAID Log'!$1:$1,0)),"")))
... A880: =IF($B880="","",IF(IFERROR(INDEX('RAID Log'!$1:$1048576,$B880,MATCH("RAID ID",'RAID Log'!$1:$1,0)),"")="","",IFERROR(INDEX('RAID Log'!$1:$1048576,$B880,MATCH("RAID ID",'RAID Log'!$1:$1,0)),""))) | B880: =IFERROR(MATCH(ROW()-1,'RAID Log'!$S:$S,0),"") | C880: =IF($B880="","",IF(IFERROR(INDEX('RAID Log'!$1:$1048576,$B880,MATCH("Description",'RAID Log'!$1:$1,0)),"")="","",IFERROR(INDEX('RAID Log'!$1:$1048576,$B880,MATCH("Description",'RAID Log'!$1:$1,0)),""))) | D880: =IF($B880="","",IF(IFERROR(INDEX('RAID Log'!$1:$1048576,$B880,MATCH("Impact/Effect of the RAID",'RAID Log'!$1:$1,0)),"")="","",IFERROR(INDEX('RAID Log'!$1:$1048576,$B880,MATCH("Impact/Effect of the RAID",'RAID Log'!$1:$1,0)),""))) | E880: =IF($B880="","",IF(IFERROR(INDEX('RAID Log'!$1:$1048576,$B880,MATCH("Impact Area",'RAID Log'!$1:$1,0)),"")="","",IFERROR(INDEX('RAID Log'!$1:$1048576,$B880,MATCH("Impact Area",'RAID Log'!$1:$1,0)),""))) | F880: =IF($B880="","",IF(IFERROR(INDEX('RAID Log'!$1:$1048576,$B880,MATCH("Impact Area",'RAID Log'!$1:$1,0)),"")="","",IFERROR(INDEX('RAID Log'!$1:$1048576,$B880,MATCH("Impact Area",'RAID Log'!$1:$1,0)),""))) | G880: =IF($B880="","",IF(IFERROR(INDEX('RAID Log'!$1:$1048576,$B880,MATCH("Impact Rating",'RAID Log'!$1:$1,0)),"")="","",IFERROR(INDEX('RAID Log'!$1:$1048576,$B880,MATCH("Impact Rating",'RAID Log'!$1:$1,0)),""))) | H880: =IF($B880="","",IF(IFERROR(INDEX('RAID Log'!$1:$1048576,$B880,MATCH("Initial Probability",'RAID Log'!$1:$1,0)),"")="","",IFERROR(INDEX('RAID Log'!$1:$1048576,$B880,MATCH("Initial Probability",'RAID Log'!$1:$1,0)),""))) | I880: =IF($B880="","",(IF($G880="Severe",25,IF($G880="Major",20,IF($G880="Moderate",15,IF($G880="Minor",10,IF($G880="Insignificant",5,0))))))*IF($H880="Very High",1,IF($H880="High",0.8,IF($H880="Average",0.6,IF($H880="Low",0.4,IF($H880="Very Low",0.2,0)))))) | J880: =IF($B880="","",IF($I880>20,"Critical",IF($I880>15,"High",IF($I880>8,"Moderate",IF($I880>3,"Tolerable","Negligible"))))) | K880: =IF(OR($B880="",UPPER($L880)="CLOSED"),"",COUNTIFS($L$2:$L$880,"<>Closed",$I$2:$I$880,">"&$I880)+COUNTIFS($L$2:$L$880,"<>Closed",$I$2:$I$880,$I880,$N$2:$N$880,"<"&$N880)+COUNTIFS($L$2:$L$880,"<>Closed",$I$2:$I$880,$I880,$N$2:$N$880,$N880,$B$2:$B$880,"<"&$B880)+1) | L880: =IF($B880="","",IF(IFERROR(INDEX('RAID Log'!$1:$1048576,$B880,MATCH("Status",'RAID Log'!$1:$1,0)),"")="","",IFERROR(INDEX('RAID Log'!$1:$1048576,$B880,MATCH("Status",'RAID Log'!$1:$1,0)),""))) | M880: =IF($B880="","",IF(IFERROR(INDEX('RAID Log'!$1:$1048576,$B880,MATCH("RAID Owner",'RAID Log'!$1:$1,0)),"")="","",IFERROR(INDEX('RAID Log'!$1:$1048576,$B880,MATCH("RAID Owner",'RAID Log'!$1:$1,0)),""))) | N880: =IF($B880="","",IF(IFERROR(INDEX('RAID Log'!$1:$1048576,$B880,MATCH("Date Raised",'RAID Log'!$1:$1,0)),"")="","",IFERROR(INDEX('RAID Log'!$1:$1048576,$B880,MATCH("Date Raised",'RAID Log'!$1:$1,0)),""))) | O880: =IF($B880="","",IF(IFERROR(INDEX('RAID Log'!$1:$1048576,$B880,MATCH("Closed Date",'RAID Log'!$1:$1,0)),"")="","",IFERROR(INDEX('RAID Log'!$1:$1048576,$B880,MATCH("Closed Date",'RAID Log'!$1:$1,0)),""))) | P880: =IF($B880="","",IF(IFERROR(INDEX('RAID Log'!$1:$1048576,$B880,MATCH("Mitigation Strategy",'RAID Log'!$1:$1,0)),"")="","",IFERROR(INDEX('RAID Log'!$1:$1048576,$B880,MATCH("Mitigation Strategy",'RAID Log'!$1:$1,0)),""))) | Q880: =IF($B880="","",IF(IFERROR(INDEX('RAID Log'!$1:$1048576,$B880,MATCH("RAID Response/Plan",'RAID Log'!$1:$1,0)),"")="","",IFERROR(INDEX('RAID Log'!$1:$1048576,$B880,MATCH("RAID Response/Plan",'RAID Log'!$1:$1,0)),"")))

Sheet RAID Log
A1: RAID ID | B1: Type | C1: Category | D1: Impact Area | E1: Title | F1: Description | G1: Impact/Effect of the RAID | H1: Date Raised | I1: RAID Owner | J1: Impact Rating | K1: Initial Probability | L1: Severity | M1: Target Date | N1: Status | O1: Mitigation Strategy | P1: Next Update | Q1: Closed Date | R1: RAID Response/Plan | S1: Risk Seq
A2: 1 | B2: Risk | C2: Quality | D2: Cost | E2: Title 1 | F2: D 1 | G2: Impact and Effect 1 | H2: 45992 | I2: Owner 1 | J2: Moderate | K2: Average | L2: High | N2: Not Started | O2: Mitigate | P2: =TODAY()+1 -> 46095 | S2: =IF($B2="Risk",COUNTIF($B$2:B2,"Risk"),"") -> 1
A3: 2 | B3: Assumption | C3: Cost | D3: Other | E3: Title 2 | F3: D 2 | G3: Impact and Effect 2 | H3: 46025 | I3: Owner 2 | J3: Severe | K3: High | L3: Medium | N3: Behind | O3: Transfer | P3: =TODAY()+3 -> 46097 | S3: =IF($B3="Risk",COUNTIF($B$2:B3,"Risk"),"")
A4: 3 | B4: Dependency | C4: Stakeholder | D4: Schedule | E4: Title 3 | F4: D 3 | G4: Impact and Effect 3 | H4: 46032 | I4: Owner 3 | J4: Insignificant | K4: Very High | L4: Medium | N4: In-Progress | O4: Escalate | P4: =TODAY()+3 -> 46097 | S4: =IF($B4="Risk",COUNTIF($B$2:B4,"Risk"),"")
A5: 4 | B5: Risk | C5: Security/Compliance | D5: Security/Compliance | E5: Title 4 | F5: D 4 | G5: Impact and Effect 4 | H5: 46039 | I5: Owner 4 | J5: Minor | K5: Very High | L5: Critical | N5: Closed | O5: Accept | P5: =TODAY()+4 -> 46098 | Q5: ='RAID Log'!$H5+10 -> 46049 | S5: =IF($B5="Risk",COUNTIF($B$2:B5,"Risk"),"") -> 2
A6: 5 | B6: Issue | C6: Scope | D6: Schedule | E6: Title 5 | F6: D 5 | G6: Impact and Effect 5 | H6: 46046 | I6: Owner 5 | J6: Major | K6: Average | L6: Low | N6: Not Started | O6: Mitigate | P6: =TODAY()+3 -> 46097 | S6: =IF($B6="Risk",COUNTIF($B$2:B6,"Risk"),"")
A7: 6 | B7: Risk | C7: Stakeholder | D7: Security/Compliance | E7: Title 6 | F7: D 6 | G7: Impact and Effect 6 | H7: 46053 | I7: Owner 6 | J7: Moderate | K7: Very Low | L7: High | N7: Behind | O7: Escalate | P7: =TODAY()+3 -> 46097 | S7: =IF($B7="Risk",COUNTIF($B$2:B7,"Risk"),"") -> 3
A8: 7 | B8: Assumption | C8: Security/Compliance | D8: Cost | E8: Title 7 | F8: D 7 | G8: Impact and Effect 7 | H8: 46060 | I8: Owner 7 | J8: Severe | K8: Average | L8: Medium | N8: Not Started | O8: Transfer | P8: =TODAY()+7 -> 46101 | S8: =IF($B8="Risk",COUNTIF($B$2:B8,"Risk"),"")
A9: 8 | B9: Dependency | C9: Scope | D9: Other | E9: Title 8 | F9: D 8 | G9: Impact and Effect 8 | H9: 46067 | I9: Owner 8 | J9: Insignificant | K9: High | L9: Medium | N9: Behind | O9: Avoid | P9: =TODAY()+3 -> 46097 | S9: =IF($B9="Risk",COUNTIF($B$2:B9,"Risk"),"")
A10: 9 | B10: Risk | C10: Technical | D10: Schedule | E10: Title 9 | F10: D 9 | G10: Impact and Effect 9 | H10: 46074 | I10: Owner 9 | J10: Minor | K10: Very High | L10: Critical | N10: In-Progress | O10: Avoid | P10: =TODAY() -> 46094 | S10: =IF($B10="Risk",COUNTIF($B$2:B10,"Risk"),"") -> 4
A11: 10 | B11: Issue | C11: Process | D11: Security/Compliance | E11: Title 10 | F11: D 10 | G11: Impact and Effect 10 | H11: 46081 | I11: Owner 10 | J11: Major | K11: Very High | L11: Low | N11: In-Progress | O11: Accept | P11: =TODAY()+13 -> 46107 | Q11: ='RAID Log'!$H11+10 -> 46091 | S11: =IF($B11="Risk",COUNTIF($B$2:B11,"Risk"),"")
A12: 11 | B12: Risk | C12: Process | D12: Cost | E12: Title 11 | F12: D 11 | G12: Impact and Effect 11 | H12: 46046 | I12: Owner 11 | J12: Moderate | K12: Average | L12: High | N12: In-Progress | O12: Mitigate | P12: =TODAY()+23 -> 46117 | S12: =IF($B12="Risk",COUNTIF($B$2:B12,"Risk"),"") -> 5
A13: 12 | B13: Assumption | C13: Resource | D13: Other | E13: Title 12 | F13: D 12 | G13: Impact and Effect 12 | H13: 46053 | I13: Owner 12 | J13: Severe | K13: Very Low | L13: Medium | N13: Closed | O13: Accept | P13: =TODAY()+3 -> 46097 | Q13: ='RAID Log'!$H13+10 -> 46063 | S13: =IF($B13="Risk",COUNTIF($B$2:B13,"Risk"),"")
A14: 13 | B14: Dependency | C14: Scope | D14: Quality | E14: Title 13 | F14: D 13 | G14: Impact and Effect 13 | H14: 46060 | I14: Owner 2 | J14: Insignificant | K14: High | L14: Medium | N14: Not Started | O14: Transfer | P14: =TODAY()+3 -> 46097 | S14: =IF($B14="Risk",COUNTIF($B$2:B14,"Risk"),"")
